Workbook

Sheet Dashboard

Sheet Data
Q2: v10-8-17-25
B3: Organisation: | C3: VitiTech
B4: Tenant ID: | C4: 71f09508-9440-42f5-8457-adb01bd21945
B5: SharePoint Admin Site: | C5: https://tumekecloud-admin.sharepoint.com
B6: Consultant: | C6: Bob Dobalina
B7: Report Date | C7: 2026-08-10 15:46:04
B8: Report File: | C8: VitiTech.Softcat-T2T-Assessment-Report-20260810-154611.xlsx
B11: Accounts | C11: Total | D11: Enabled | E11: Licensed | F11: Sync'd
B12: Member | C12: =COUNTIF(AllUsers!E:E,"Member") -> 0 | D12: =SUMPRODUCT((#REF!="Member")*(#REF!="True")) -> #REF! | E12: =COUNTIFS(#REF!,"Member",#REF!,"<>") -> #REF! | F12: =SUMPRODUCT((#REF!="Member")*(#REF!="True")) -> #REF!
B13: Guest | C13: =COUNTIF(AllUsers!E:E,"Guest") -> 0 | D13: =SUMPRODUCT((#REF!="Guest")*(#REF!="True")) -> #REF! | E13: =COUNTIFS(#REF!,"Guest",#REF!,"<>") -> #REF! | F13: =SUMPRODUCT((#REF!="Guest")*(#REF!="True")) -> #REF!
B14: Contacts | C14: =COUNTIF(Contacts!E:E,"MailContact") -> 0
B16: Data | C16: GB
B17: Mailbox | C17: =SUM(D32,D36,D40) -> 0
B18: OneDrives | C18: =D45 -> 0
B19: SharePoint | C19: =D52 -> 0
C20: =SUM(C17:C19) -> 0
B26: Mailboxes | J26: Devices
B27: Type | C27: # | D27: GB | E27: Items | F27: Hold | J27: Type | K27: # | L27: Registered | M27: Joined | N27: Hybrid | O27: Active 30 days
B28: User | C28: =COUNTIF(AccountSummary!A:A,"UserMailbox") -> 0 | D28: =_xlfn.LET(_xlpm.total,SUMIF(AccountSummary!A:A,"UserMailbox",AccountSummary!G:G)/1024,IF(C28<1,"0",IF(ROUND(_xlpm.total,2)=0,0.01,_xlpm.total))) -> 0 | E28: =IF(C28<1,"0",SUMIF(AccountSummary!A:A,"UserMailbox",AccountSummary!F:F)) -> 0 | F28: =SUMPRODUCT((#REF!="UserMailbox")*(#REF!="True")) -> #REF! | J28: Windows | K28: =COUNTIF(Devices!B:B,"Windows") -> 0 | L28: =SUMPRODUCT((#REF!="Windows")*(#REF!="Entra Registered")) -> #REF! | M28: =SUMPRODUCT((#REF!="Windows")*(#REF!="Entra Joined")) -> #REF! | N28: =SUMPRODUCT((#REF!="Windows")*(#REF!="Entra Hybrid Joined")) -> #REF!
B29: Shared | C29: =COUNTIF(AccountSummary!A:A,"SharedMailbox") -> 0 | D29: =_xlfn.LET(_xlpm.total,SUMIF(AccountSummary!A:A,"SharedMailbox",AccountSummary!G:G)/1024,IF(C29<1,"0",IF(ROUND(_xlpm.total,2)=0,0.01,_xlpm.total))) -> 0 | E29: =IF(C29<1,"0",SUMIF(AccountSummary!A:A,"SharedMailbox",AccountSummary!F:F)) -> 0 | F29: =SUMPRODUCT((#REF!="SharedMailbox")*(#REF!="True")) -> #REF! | J29: Android | K29: =COUNTIF(Devices!B:B,"Windows") -> 0
B30: Equipment | C30: =COUNTIF(AccountSummary!A:A,"EquipmentMailbox") -> 0 | D30: =_xlfn.LET(_xlpm.total,SUMIF(AccountSummary!A:A,"EquipmentMailbox",AccountSummary!G:G)/1024,IF(C30<1,"0",IF(ROUND(_xlpm.total,2)=0,0.01,_xlpm.total))) -> 0 | E30: =IF(C30<1,"0",SUMIF(AccountSummary!A:A,"EquipmentMailbox",AccountSummary!F:F)) -> 0 | F30: =SUMPRODUCT((#REF!="EquipmentMailbox")*(#REF!="True")) -> #REF! | J30: iOS | K30: =COUNTIF(Devices!B:B,"Windows") -> 0
B31: Room | C31: =COUNTIF(AccountSummary!A:A,"RoomMailbox") -> 0 | D31: =_xlfn.LET(_xlpm.total,SUMIF(AccountSummary!A:A,"RoomMailbox",AccountSummary!G:G)/1024,IF(C31<1,"0",IF(ROUND(_xlpm.total,2)=0,0.01,_xlpm.total))) -> 0 | E31: =IF(C31<1,"0",SUMIF(AccountSummary!A:A,"RoomMailbox",AccountSummary!F:F)) -> 0 | F31: =SUMPRODUCT((#REF!="RoomMailbox")*(#REF!="True")) -> #REF!
B32: Total User Mailboxes | C32: =SUM(C28:C31) -> 0 | D32: =SUM(D28:D31) -> 0 | E32: =SUM(E28:E31) -> 0
B34: Microsoft 365 Group Mailboxes | C34: =COUNTIF(GroupSummary!A:A,"M365 Group") -> 0 | D34: =_xlfn.LET(_xlpm.total,SUMIF(GroupSummary!A:A,"M365 Group",GroupSummary!F:F)/1024,IF(C28<1,"0",IF(ROUND(_xlpm.total,2)=0,0.01,_xlpm.total))) -> 0 | E34: =IF(C34<1,"0",SUMIF(GroupSummary!A:A,"M365 Group",GroupSummary!E:E)) -> 0
B35: Microsoft Teams Mailboxes | C35: =COUNTIF(GroupSummary!A:A,"Team") -> 0 | D35: =_xlfn.LET(_xlpm.total,SUMIF(GroupSummary!A:A,"Team",GroupSummary!F:F)/1024,IF(C29<1,"0",IF(ROUND(_xlpm.total,2)=0,0.01,_xlpm.total))) -> 0 | E35: =IF(C35<1,"0",SUMIF(GroupSummary!A:A,"Team",GroupSummary!E:E)) -> 0
B36: Total Unified Group Mailboxes | C36: =SUM(C34:C35) -> 0 | D36: =SUM(D34:D35) -> 0 | E36: =SUM(E34:E35) -> 0
B38: Total | C38: =SUM(C32,C36,C40) -> #REF! | D38: =SUM(D32,D36,D40) -> 0 | E38: =SUM(E32,E36) -> 0
B40: Archive Mailboxes | C40: =SUMPRODUCT(--(LEN(TRIM(#REF!&""))>0)) -> #REF! | D40: =SUM(AccountSummary!H:H) -> 0
B43: OneDrives
B44: Type | C44: # | D44: GB
B45: Active | C45: =COUNTIF(OneDrives!F:F,"Active") -> 0 | D45: =SUM(OneDrives!C:C)/1024 -> 0
B47: SharePoint Sites
B48: Type | C48: # | D48: GB
B49: SharePoint | C49: =COUNTIF(SharePointSites!A:A,"SharePoint Site") -> 0 | D49: =_xlfn.LET(_xlpm.total,SUMIF(SharePointSites!A:A,"SharePoint Site",SharePointSites!D:D)/1024,IF(C49<1,"0",IF(ROUND(_xlpm.total,2)=0,0.01,_xlpm.total))) -> 0
B50: M365 Group | C50: =COUNTIF(SharePointSites!A:A,"M365 Group") -> 0 | D50: =_xlfn.LET(_xlpm.total,SUMIF(SharePointSites!A:A,"M365 Group",SharePointSites!D:D)/1024,IF(C50<1,"0",IF(ROUND(_xlpm.total,2)=0,0.01,_xlpm.total))) -> 0
B51: Team | C51: =COUNTIF(SharePointSites!A:A,"Team") -> 0 | D51: =_xlfn.LET(_xlpm.total,SUMIF(SharePointSites!A:A,"Team",SharePointSites!D:D)/1024,IF(C51<1,"0",IF(ROUND(_xlpm.total,2)=0,0.01,_xlpm.total))) -> 0
C52: =SUM(C49:C51) -> 0 | D52: =SUM(D49:D51) -> 0
B54: Groups
B55: Type | C55: #
B56: MailEnabledSecurityGroups | C56: =MAX(0,COUNTA(MailEnabledSecurityGroups!B:B)-1) -> 0
...

Sheet AllUsers

Sheet AccountSummary

Sheet Devices

Sheet GroupSummary

Sheet OneDrives

Sheet SharePointSites

Sheet Contacts

Sheet Domains

Sheet MailEnabledSecurityGroups

Sheet DynamicDistributionGroups

Sheet DistributionGroups

Sheet SecurityGroups

Sheet AccountMailboxes

Sheet GroupMailboxes

Sheet Sheet1
